Workbook
Name Excel_BuiltIn__FilterDatabase: Hoja2_2!$A$1:$R$110

Sheet Hoja2_2
A1: N.º | B1: Cédula | C1: Apellido(s) | D1: Nombre (s) | E1: Escuela(s) | F1: N° de Personal | G1: Fecha Aniversaria | H1: Años Servicio | I1: Correspondiente al Periodo vacacional: | J1: Desde | K1: Hasta | L1: Total Días | M1: Correspondiente al Periodo (s) vacacional: | N1: Indicador | O1: Teléfono | P1: Supervisor Inmed. / Indicador /Tlf | Q1: Cédula | R1: Cargo Actual
A2: 1 | B2: 19603449 | C2: ACOSTA | D2: PATRICIA | E2: UE LIBERTADOR BOLÍVAR | F2: 2247672 | G2: 43473 | H2: 7 | I2: 2026 | J2: 46235 | K2: 46280 | L2: 46 | M2: 2026 | N2: ACOSTAPH | O2: 0426-7200383 | P2: LUIS ALFREDO VELÁSQUEZ ALCÁZAR | Q2: 17242954 | R2: ESPECIALISTA EN DIFICULTADES DE APRENDIZ
A3: 2 | B3: 18463516 | C3: AGUILERA | D3: VIRGINIA | E3: UE LIBERTADOR BOLÍVAR | F3: 2247620 | G3: 44214 | H3: 5 | I3: 2026 | J3: 46235 | K3: 46280 | L3: 46 | M3: 2026 | N3: AGUILERAVS | O3: 0424-9202587 | P3: LUIS ALFREDO VELÁSQUEZ ALCÁZAR | Q3: 17242954 | R3: DOCENTE MEDIA GENERAL
A4: 3 | B4: 18172869 | C4: ALBORNOZ | D4: ISABEL | E4: UE LIBERTADOR BOLÍVAR | F4: 2247630 | G4: 43473 | H4: 7 | I4: 2026 | J4: 46235 | K4: 46280 | L4: 46 | M4: 2026 | N4: ALBORNOZIH | O4: 0426-3981776 | P4: LUIS ALFREDO VELÁSQUEZ ALCÁZAR | Q4: 17242954 | R4: DOCENTE EDUCACIÓN INICIAL
A5: 4 | B5: 13092755 | C5: BARRETO | D5: KARINA | E5: UE LIBERTADOR BOLÍVAR | F5: 2078111 | G5: 38302 | H5: 21 | I5: 2026 | J5: 46235 | K5: 46280 | L5: 46 | M5: 2026 | N5: BARRETOKD | O5: 0416-1948996 | P5: LUIS ALFREDO VELÁSQUEZ ALCÁZAR | Q5: 17242954 | R5: DOCENTE MEDIA GENERAL
A6: 5 | B6: 18274289 | C6: BEJAS | D6: SULMARY | E6: UE LIBERTADOR BOLÍVAR | F6: 2247628 | G6: 43473 | H6: 7 | I6: 2026 | J6: 46235 | K6: 46280 | L6: 46 | M6: 2026 | N6: BEJASS | O6: 0424-9329569 | P6: LUIS ALFREDO VELÁSQUEZ ALCÁZAR | Q6: 17242954 | R6: DOCENTE MEDIA GENERAL
A7: 6 | B7: 22718748 | C7: BERMUDEZ GONZALEZ | D7: FRANCHESCA G | E7: UE LIBERTADOR BOLÍVAR | F7: 8065643 | G7: 44942 | H7: 3 | I7: 2026 | J7: 46235 | K7: 46280 | L7: 46 | M7: 2026 | O7: 0424-9651651 | P7: LUIS ALFREDO VELÁSQUEZ ALCÁZAR | Q7: 17242954 | R7: DOCENTE PRIMARIA
A8: 7 | B8: 16722294 | C8: BRITO | D8: JESLHOR | E8: UE LIBERTADOR BOLÍVAR | F8: 2205978 | G8: 41624 | H8: 12 | I8: 2026 | J8: 46235 | K8: 46280 | L8: 46 | M8: 2026 | N8: BRITOJKX | O8: 0412-9487630 | P8: LUIS ALFREDO VELÁSQUEZ ALCÁZAR | Q8: 17242954 | R8: DOCENTE PRIMARIA
A9: 8 | B9: 14859067 | C9: CANELON | D9: JUAN | E9: UE LIBERTADOR BOLÍVAR | F9: 2247674 | G9: 43473 | H9: 7 | I9: 2026 | J9: 46235 | K9: 46280 | L9: 46 | M9: 2026 | N9: CANELONJN | O9: 0424-4238157 | P9: LUIS ALFREDO VELÁSQUEZ ALCÁZAR | Q9: 17242954 | R9: DOCENTE MEDIA GENERAL
A10: 9 | B10: 17483709 | C10: CELIZ | D10: LORIANIS | E10: UE LIBERTADOR BOLÍVAR | F10: 2177721 | G10: 41222 | H10: 13 | I10: 2026 | J10: 46235 | K10: 46280 | L10: 46 | M10: 2026 | N10: CELIZL | O10: 0412-9494450 | P10: LUIS ALFREDO VELÁSQUEZ ALCÁZAR | Q10: 17242954 | R10: DOCENTE MEDIA GENERAL
A11: 10 | B11: 19080636 | C11: DIAZ MOLINA | D11: MOLINA CAROLINA | E11: UE LIBERTADOR BOLÍVAR | F11: 2209335 | G11: 41753 | H11: 12 | I11: 2026 | J11: 46235 | K11: 46280 | L11: 46 | M11: 2026 | N11: DIAZPCX | O11: 0416-9900981 | P11: LUIS ALFREDO VELÁSQUEZ ALCÁZAR | Q11: 17242954 | R11: PSICOPEDAGOGO
A12: 11 | B12: 16807474 | C12: DURAN | D12: TRINELLYS | E12: UE LIBERTADOR BOLÍVAR | F12: 2137991 | G12: 39904 | H12: 17 | I12: 2026 | J12: 46235 | K12: 46280 | L12: 46 | M12: 2026 | N12: DURAMTN | O12: 0424-9188018 | P12: LUIS ALFREDO VELÁSQUEZ ALCÁZAR | Q12: 17242954 | R12: DOCENTE PRIMARIA
A13: 12 | B13: 15335432 | C13: FIGUEROA G. | D13: TEOBALDO | E13: UE LIBERTADOR BOLÍVAR | F13: 2079830 | G13: 38412 | H13: 21 | I13: 2026 | J13: 46235 | K13: 46280 | L13: 46 | M13: 2026 | N13: FIGUEROAT | O13: 0416-6976328 | P13: LUIS ALFREDO VELÁSQUEZ ALCÁZAR | Q13: 17242954 | R13: SUDIRECTOR ADMINISTRATIVO
A14: 13 | B14: 19038253 | C14: FUENMAYOR LIPORACHI | D14: ISLENY ADR | E14: UE LIBERTADOR BOLÍVAR | F14: 2209264 | G14: 41754 | H14: 12 | I14: 2026 | J14: 46235 | K14: 46280 | L14: 46 | M14: 2026 | N14: FUENMAYORIS | O14: 0424-9091817 | P14: LUIS ALFREDO VELÁSQUEZ ALCÁZAR | Q14: 17242954 | R14: DOCENTE MEDIA GENERAL
A15: 14 | B15: 12067865 | C15: GARCIA ARENAS | D15: NEIDA | E15: UE LIBERTADOR BOLÍVAR | F15: 2206179 | G15: 41628 | H15: 12 | I15: 2026 | J15: 46235 | K15: 46280 | L15: 46 | M15: 2026 | N15: GARCIANML | O15: 0414-9989327 | P15: LUIS ALFREDO VELÁSQUEZ ALCÁZAR | Q15: 17242954 | R15: DOCENTE PRIMARIA
A16: 15 | B16: 17933097 | C16: GARCIA LAREZ | D16: YENIRE | E16: UE LIBERTADOR BOLÍVAR | F16: 2247631 | G16: 43473 | H16: 7 | I16: 2026 | J16: 46235 | K16: 46280 | L16: 46 | M16: 2026 | N16: GARCIAYTH | O16: 0416-7860704 | P16: LUIS ALFREDO VELÁSQUEZ ALCÁZAR | Q16: 17242954 | R16: DOCENTE EDUCACIÓN INICIAL
A17: 16 | B17: 14367610 | C17: GONZALEZ | D17: ANA | E17: UE LIBERTADOR BOLÍVAR | F17: 2090264 | G17: 38631 | H17: 20 | I17: 2026 | J17: 46235 | K17: 46280 | L17: 46 | M17: 2026 | N17: GONZALEZAEG | O17: 0424-9464834 | P17: LUIS ALFREDO VELÁSQUEZ ALCÁZAR | Q17: 17242954 | R17: COORDINADOR DE EVALUACIÓN
A18: 17 | B18: 17546584 | C18: GONZALEZ | D18: ELIANA LIZKEIRA | E18: UE LIBERTADOR BOLÍVAR | F18: 2177712 | G18: 41008 | H18: 14 | I18: 2026 | J18: 46235 | K18: 46280 | L18: 46 | M18: 2026 | N18: GONZALEZEKB | O18: 0412-1275548 | P18: LUIS ALFREDO VELÁSQUEZ ALCÁZAR | Q18: 17242954 | R18: DOCENTE MEDIA GENERAL
A19: 18 | B19: 18788707 | C19: GONZALEZ | D19: YASIVIT | E19: UE LIBERTADOR BOLÍVAR | F19: 2177808 | G19: 41008 | H19: 14 | I19: 2026 | J19: 46235 | K19: 46280 | L19: 46 | M19: 2026 | N19: GONZALEZYDT | O19: 0416-9062003 | P19: LUIS ALFREDO VELÁSQUEZ ALCÁZAR | Q19: 17242954 | R19: SUDIRECTOR ACADÉMICO
A20: 19 | B20: 20001991 | C20: GONZALEZ BARCELO | D20: JUAN | E20: UE LIBERTADOR BOLÍVAR | F20: 2247622 | G20: 44596 | H20: 4 | I20: 2026 | J20: 46235 | K20: 46280 | L20: 46 | M20: 2026 | N20: GONZALEZJA | O20: 0424-9288814 | P20: LUIS ALFREDO VELÁSQUEZ ALCÁZAR | Q20: 17242954 | R20: DOCENTE PRIMARIA
A21: 20 | B21: 22720162 | C21: GONZALEZ TREJO | D21: NOHELY SORIBEL | E21: UE LIBERTADOR BOLÍVAR | F21: 8065646 | G21: 44942 | H21: 3 | I21: 2026 | J21: 46235 | K21: 46280 | L21: 46 | M21: 2026 | O21: 0414-8637262 | P21: LUIS ALFREDO VELÁSQUEZ ALCÁZAR | Q21: 17242954 | R21: DOCENTE MEDIA GENERAL
A22: 21 | B22: 19079220 | C22: GONZALEZ VARGAS | D22: BETZAIDA ZARAY | E22: UE LIBERTADOR BOLÍVAR | F22: 8044828 | G22: 43707 | H22: 6 | I22: 2026 | J22: 46235 | K22: 46280 | L22: 46 | M22: 2026 | N22: GONZALEZBZX | O22: 0416-9824842 | P22: LUIS ALFREDO VELÁSQUEZ ALCÁZAR | Q22: 17242954 | R22: DOCENTE MEDIA GENERAL
A23: 22 | B23: 18075785 | C23: GONZALEZ YANEZ | D23: EYLLING KEYROVI | E23: UE LIBERTADOR BOLÍVAR | F23: 8065641 | G23: 44942 | H23: 3 | I23: 2026 | J23: 46235 | K23: 46280 | L23: 46 | M23: 2026 | O23: 0412-2406062 | P23: LUIS ALFREDO VELÁSQUEZ ALCÁZAR | Q23: 17242954 | R23: DOCENTE PRIMARIA
A24: 23 | B24: 12891949 | C24: HERNANDEZ | D24: DENYSSE JOSEFINA | E24: UE LIBERTADOR BOLÍVAR | F24: 4007923 | G24: 38621 | H24: 20 | I24: 2026 | J24: 46235 | K24: 46280 | L24: 46 | M24: 2026 | N24: HERNADEZDJY | O24: 0424-5725526 | P24: LUIS ALFREDO VELÁSQUEZ ALCÁZAR | Q24: 17242954 | R24: DEFENSOR ESCOLAR
A25: 24 | B25: 16374774 | C25: HURTADO | D25: ELINOR DEL VALLE | E25: UE LIBERTADOR BOLÍVAR | F25: 2209248 | G25: 41754 | H25: 12 | I25: 2026 | J25: 46235 | K25: 46280 | L25: 46 | M25: 2026 | N25: HURTADOEQ | O25: 0412-3340579 | P25: LUIS ALFREDO VELÁSQUEZ ALCÁZAR | Q25: 17242954 | R25: DOCENTE MEDIA GENERAL
A26: 25 | B26: 19080588 | C26: JIMENEZ ANGULO | D26: JOSE ALY | E26: UE LIBERTADOR BOLÍVAR | F26: 8065654 | G26: 44942 | H26: 3 | I26: 2026 | J26: 46235 | K26: 46280 | L26: 46 | M26: 2026 | O26: 0412-8783907 | P26: LUIS ALFREDO VELÁSQUEZ ALCÁZAR | Q26: 17242954 | R26: DOCENTE MEDIA GENERAL
A27: 26 | B27: 17722878 | C27: JIMENEZ MATA | D27: JAMNYMAR JOSE | E27: UE LIBERTADOR BOLÍVAR | F27: 2162520 | G27: 40470 | H27: 15 | I27: 2026 | J27: 46235 | K27: 46280 | L27: 46 | M27: 2026 | N27: JIMENEZJJQ | O27: 0414-7686402 | P27: LUIS ALFREDO VELÁSQUEZ ALCÁZAR | Q27: 17242954 | R27: DOCENTE EDUCACIÓN INICIAL
A28: 27 | B28: 17723779 | C28: JIMENEZ NUNEZ | D28: LUISA | E28: UE LIBERTADOR BOLÍVAR | F28: 2247675 | G28: 43473 | H28: 7 | I28: 2026 | J28: 46235 | K28: 46280 | L28: 46 | M28: 2026 | N28: JIMENEZLAW | O28: 0414-7701960 | P28: LUIS ALFREDO VELÁSQUEZ ALCÁZAR | Q28: 17242954 | R28: ESPECIALISTA EN DIFICULTADES DE APRENDIZ
A29: 28 | B29: 16375125 | C29: LEON | D29: EIRA A | E29: UE LIBERTADOR BOLÍVAR | F29: 2137952 | G29: 39904 | H29: 17 | I29: 2026 | J29: 46235 | K29: 46280 | L29: 46 | M29: 2026 | N29: LEONEAY | O29: 0414-9918333 | P29: LUIS ALFREDO VELÁSQUEZ ALCÁZAR | Q29: 17242954 | R29: DOCENTE MEDIA GENERAL
A30: 29 | B30: 16699098 | C30: LOPEZ | D30: FERNANDA | E30: UE LIBERTADOR BOLÍVAR | F30: 2247624 | G30: 43473 | H30: 7 | I30: 2026 | J30: 46235 | K30: 46280 | L30: 46 | M30: 2026 | N30: LOPEZFAF | O30: 0424-9554985 | P30: LUIS ALFREDO VELÁSQUEZ ALCÁZAR | Q30: 17242954 | R30: DOCENTE PRIMARIA
A31: 30 | B31: 18080019 | C31: LOPEZ TORRES | D31: NELLYS JOSEFINA | E31: UE LIBERTADOR BOLÍVAR | F31: 8065638 | G31: 44942 | H31: 3 | I31: 2026 | J31: 46235 | K31: 46280 | L31: 46 | M31: 2026 | O31: 0412-8655197 | P31: LUIS ALFREDO VELÁSQUEZ ALCÁZAR | Q31: 17242954 | R31: DOCENTE PRIMARIA
A32: 31 | B32: 14703619 | C32: LUCAS | D32: JOSE | E32: UE LIBERTADOR BOLÍVAR | F32: 2177720 | G32: 41008 | H32: 14 | I32: 2026 | J32: 46235 | K32: 46280 | L32: 46 | M32: 2026 | N32: LUCASJN | O32: 0416-7926910 | P32: LUIS ALFREDO VELÁSQUEZ ALCÁZAR | Q32: 17242954 | R32: DOCENTE MEDIA GENERAL
A33: 32 | B33: 17090701 | C33: MAITA | D33: YARITZA G | E33: UE LIBERTADOR BOLÍVAR | F33: 2138245 | G33: 39925 | H33: 17 | I33: 2026 | J33: 46235 | K33: 46280 | L33: 46 | M33: 2026 | N33: MAITAYG | O33: 0412-0913435 | P33: LUIS ALFREDO VELÁSQUEZ ALCÁZAR | Q33: 17242954 | R33: DOCENTE MEDIA GENERAL
A34: 33 | B34: 15631248 | C34: MARCANO | D34: YUDERCY | E34: UE LIBERTADOR BOLÍVAR | F34: 2247671 | G34: 43473 | H34: 7 | I34: 2026 | J34: 46235 | K34: 46280 | L34: 46 | M34: 2026 | N34: MARCANOYAX | O34: 0426-0355870 | P34: LUIS ALFREDO VELÁSQUEZ ALCÁZAR | Q34: 17242954 | R34: PSICOPEDAGOGO
A35: 34 | B35: 17241569 | C35: MARCANO MARTIN | D35: EDUARDO | E35: UE LIBERTADOR BOLÍVAR | F35: 2209352 | G35: 41754 | H35: 12 | I35: 2026 | J35: 46235 | K35: 46280 | L35: 46 | M35: 2026 | N35: MARCANOMEH | O35: 0412-9429171 | P35: LUIS ALFREDO VELÁSQUEZ ALCÁZAR | Q35: 17242954 | R35: DOCENTE MEDIA GENERAL
A36: 35 | B36: 14531830 | C36: MARTIN | D36: MINERVA | E36: UE LIBERTADOR BOLÍVAR | F36: 2247617 | G36: 43108 | H36: 8 | I36: 2026 | J36: 46235 | K36: 46280 | L36: 46 | M36: 2026 | N36: MARTINMJ | O36: 0416-1818890 | P36: LUIS ALFREDO VELÁSQUEZ ALCÁZAR | Q36: 17242954 | R36: DOCENTE EDUCACIÓN INICIAL
A37: 36 | B37: 14622890 | C37: MARTINEZ | D37: ALBERTO | E37: UE LIBERTADOR BOLÍVAR | F37: 2247619 | G37: 43473 | H37: 7 | I37: 2026 | J37: 46235 | K37: 46280 | L37: 46 | M37: 2026 | N37: MARTINEZARE | O37: 0426-4941095 | P37: LUIS ALFREDO VELÁSQUEZ ALCÁZAR | Q37: 17242954 | R37: DOCENTE MEDIA GENERAL
A38: 37 | B38: 17113644 | C38: MARTINEZ | D38: MILAGROS | E38: UE LIBERTADOR BOLÍVAR | F38: 2094299 | G38: 16/12/2013 | H38: 12 | I38: 2026 | J38: 46235 | K38: 46268 | L38: 34 | M38: 2026 | N38: MARTINEZMDA | O38: 0412-2980380 | P38: LUIS ALFREDO VELÁSQUEZ ALCÁZAR | Q38: 17242954 | R38: ANALISTA DE ARCHIVO
A39: 38 | B39: 17463095 | C39: MARTINEZ | D39: MARIA | E39: UE LIBERTADOR BOLÍVAR | F39: 2247634 | G39: 43473 | H39: 7 | I39: 2026 | J39: 46235 | K39: 46280 | L39: 46 | M39: 2026 | N39: MARTINEZMTN | O39: 0416-2889081 | P39: LUIS ALFREDO VELÁSQUEZ ALCÁZAR | Q39: 17242954 | R39: DOCENTE PRIMARIA
A40: 39 | B40: 20310911 | C40: MARTÍNEZ CABRERA | D40: MARÍA ALEJANDRA | E40: UE LIBERTADOR BOLÍVAR | F40: 8065634 | G40: 44942 | H40: 3 | I40: 2026 | J40: 46235 | K40: 46280 | L40: 46 | M40: 2026 | O40: 0424-9559942 | P40: LUIS ALFREDO VELÁSQUEZ ALCÁZAR | Q40: 17242954 | R40: DOCENTE PRIMARIA
...

Sheet CONDICIONES
A3: TIPO DE PRESTAMO | C3: CONDICIÓN ACTUAL HABITABILIDAD
A4: INICIAL/ADQUISICIÓN | C4: 1) Habite en condición de hacinamiento, solo o con su grupo familiar.
A5: INICIAL/MEJORAS | C5: 2) Habite en condición de arrimado, solo o con su grupo familiar.
A6: ADICIONAL/ADQUISICIÓN | C6: 3) Habite en condición de alquiler, solo o con su grupo familiar.
A7: ADICIONAL/MEJORAS | C7: 4) Habite en condición de alquiler, con solicitud u orden de desalojo.
C8: 5) Habite en vivienda catalogada de alto riesgo, así declarado por la autoridad competente (Protección Civil o Bomberos)
C9: 6) Habite en vivienda prestada, bajo su cuidado.
A10: TRABAJADOR O FAMILIAR CON DISCAPACIDAD | C10: 7) Habite en un inmueble asignado, propiedad de la Empresa.
A11: SI | C11: 8) Habite un inmueble bajo otra condición diferente a las anteriores
A12: NO
A15: CÓNYUGE O CONCUBIN@ TRABAJADOR
A16: ES TRABAJADOR(A) ACTIVO(A)
A17: TRABAJÓ, ESTÁ RETIRADO
A18: NUNCA HA TRABAJO PDVSA
A21: ORDEN DE PRIORIDAD
A22: 1.) REQUIERE ATENCIÓN INMEDIATA/CASO CRÍTICO POR ALTO RIESGO Y/O ELEVADO NIVEL DE VULNERABILIDAD
A23: 2.) REQUIERE ATENCIÓN MEDIA (DEBE ATENDERSE DESPUÉS DE CASOS CRÍTICOS)
A24: 3.) REQUIERE ATENCIÓN NORMAL

Sheet GERENCIA 
A1: ESTRICTAMENTE CONFIDENCIAL
B2: Gerencia: | C2: Recursos Humanos
B3: Total FLE: | C3: 60
B4: Total trabajadores elegibles al PAAV: 47
B5: Total casos críticos:
A7: N | B7: CEDULA | C7: APELLIDOS Y NOMBRES | D7: GERENCIA | E7: PROCESO | F7: FECHA INGRESO | G7: ANTIGÜEDAD | H7: CARGA FAMILIAR SAP | I7: NUM HIJOS SAP | J7: CRITICIDAD | K7: TIPO DE PRÉSTAMO / MOTIVO DEL PRÉSTAMO | L7: ¿CUÁNTAS PERSONAS CONVIVEN EN EL NÚCLEO FAMILIAR DEL TRABAJADOR? | M7: ¿TRABAJADOR TIENE DISCAPACIDAD AVALADA POR EL CONAPDIS? | N7: OBSERVACIONES | O7: FAMILIAR CON DISCAPACIDAD AVALADA POR EL CONAPDIS? | P7: OBSERVACIONES | Q7: NOMBRE A APELLIDO DEL CÓNYUGE O CONCUBINA | R7: CÉDULA DE LA CÓNYUGE O CONCUBINA | S7: CÓNYUGE O CONCUBINA TRABAJA O TRABAJÓ EN PDVSA | T7: CONDICIÓN ACTUAL HABITABILIDAD | U7: OBSERVACIONES | V7: ORDEN DE PRIORIDAD | W7: se | AB7: 1
A8: 1 | B8: 17780095 | C8: JOSÉ VICENTE MILLÁN MONTAÑO | D8: RECURSOS HUMANOS | E8: ESCUELA | F8: =VLOOKUP(B8,Hoja2_2!$B$2:$G$110,6,0) -> 41127 | G8: =DATEDIF(F8,TODAY(),"y") -> 13 | K8: ADICIONAL/ADQUISICIÓN | L8: 3 | M8: NO | N8: SOLICITADO | O8: No | Q8: LORIANIS ZULLY CELIZ CASTILLO | R8: 17483709 | S8: ES TRABAJADOR(A) ACTIVO(A) | T8: 6) Habite en vivienda prestada, bajo su cuidado.
A9: 2 | B9: 18788707 | C9: YASIVIT DEL VALLE GONZÁLEZ GUISSEPPI | D9: RECURSOS HUMANOS | E9: ESCUELA | F9: =VLOOKUP(B9,Hoja2_2!$B$2:$G$110,6,0) -> 41008 | G9: =DATEDIF(F9,TODAY(),"y") -> 14 | K9: ADICIONAL/MEJORAS | L9: 3 | M9: NO | N9: SOLICITADO | O9: No | Q9: LUIS ALFREDO VELÁSQUEZ ALCAZAR | R9: 17242954 | S9: ES TRABAJADOR(A) ACTIVO(A) | T9: 8) Habite un inmueble bajo otra condición diferente a las anteriores
A10: 3 | B10: 14367610 | C10: ANA ELIUT GONZALEZ SALAZAR | D10: RECURSOS HUMANOS | E10: ESCUELA | F10: =VLOOKUP(B10,Hoja2_2!$B$2:$G$110,6,0) -> 38631 | G10: =DATEDIF(F10,TODAY(),"y") -> 20 | K10: ADICIONAL/MEJORAS | L10: 3 | M10: NO | N10: SOLICITADO | O10: No | Q10: DARWIN JOSÉ CORDERO GALLARDO | R10: 12538506 | S10: NUNCA HA TRABAJO PDVSA | T10: 8) Habite un inmueble bajo otra condición diferente a las anteriores
A11: 4 | B11: 14101477 | C11: MARYFRANCI ANYALI NORIEGA BARRETO | D11: RECURSOS HUMANOS | E11: ESCUELA | F11: =VLOOKUP(B11,Hoja2_2!$B$2:$G$110,6,0) -> 38412 | G11: =DATEDIF(F11,TODAY(),"y") -> 21 | K11: ADICIONAL/MEJORAS | L11: 3 | M11: NO | N11: SOLICITADO | O11: No | Q11: LUIS LORENZO VÉLIZ MOROCOIMA | R11: 11446707 | S11: NUNCA HA TRABAJO PDVSA | T11: 8) Habite un inmueble bajo otra condición diferente a las anteriores
A12: 5 | B12: 9286272 | C12: CARMEN ELENA RODRÍGUEZ PINTO | D12: RECURSOS HUMANOS | E12: ESCUELA | F12: =VLOOKUP(B12,Hoja2_2!$B$2:$G$110,6,0) -> 34613 | G12: =DATEDIF(F12,TODAY(),"y") -> 31 | K12: ADICIONAL/MEJORAS | L12: 2 | M12: NO | N12: PAGADO | O12: No | Q12: JUAN ANTONIO CERVANTES BROWN | R12: 84603455 | S12: NUNCA HA TRABAJO PDVSA | T12: 8) Habite un inmueble bajo otra condición diferente a las anteriores
A13: 6 | B13: 14110180 | C13: JUAN ENRIQUE ZAMBRANO RONDON | D13: RECURSOS HUMANOS | E13: ESCUELA | F13: =VLOOKUP(B13,Hoja2_2!$B$2:$G$110,6,0) -> 41008 | G13: =DATEDIF(F13,TODAY(),"y") -> 14 | K13: INICIAL/ADQUISICIÓN | L13: 2 | M13: NO | N13: PAGANDOLO | O13: No | Q13: NORKYS KARYNY HERNÁNDEZ MACHUCA | R13: 14703374 | S13: NUNCA HA TRABAJO PDVSA | T13: 8) Habite un inmueble bajo otra condición diferente a las anteriores
A14: 7 | B14: 14622890 | C14: ALBERTO RAFAEL MARTINEZ VILLAHERMOSA | D14: RECURSOS HUMANOS | E14: ESCUELA | F14: =VLOOKUP(B14,Hoja2_2!$B$2:$G$110,6,0) -> 43473 | G14: =DATEDIF(F14,TODAY(),"y") -> 7 | K14: INICIAL/ADQUISICIÓN | L14: 2 | M14: NO | N14: SOLICITADO | O14: No | Q14: YUSMERYS VALDIVIEZO | R14: 11006024 | S14: NUNCA HA TRABAJO PDVSA | T14: 2) Habite en condición de arrimado, solo o con su grupo familiar.
A15: 8 | B15: 13915005 | C15: BEATRÍZ JOSEFINA NUCCI CORTÉZ | D15: RECURSOS HUMANOS | E15: ESCUELA | F15: =VLOOKUP(B15,Hoja2_2!$B$2:$G$110,6,0) -> 37907 | G15: =DATEDIF(F15,TODAY(),"y") -> 22 | K15: ADICIONAL/MEJORAS | L15: 2 | M15: NO | N15: SOLICITADO | O15: No | T15: 8) Habite un inmueble bajo otra condición diferente a las anteriores
A16: 9 | B16: 22714341 | C16: DANIELA CAROLINA PERNIA HENRIQUEZ | D16: RECURSOS HUMANOS | E16: ESCUELA | F16: =VLOOKUP(B16,Hoja2_2!$B$2:$G$110,6,0) -> 43473 | G16: =DATEDIF(F16,TODAY(),"y") -> 7 | K16: INICIAL/ADQUISICIÓN | L16: 2 | M16: NO | N16: SOLICITADO | O16: No | T16: 1) Habite en condición de hacinamiento, solo o con su grupo familiar.
A17: 10 | B17: 12891949 | C17: DENYSSE JOSEFINA HERNANDEZ MACHADO | D17: RECURSOS HUMANOS | E17: ESCUELA | F17: =VLOOKUP(B17,Hoja2_2!$B$2:$G$110,6,0) -> 38621 | G17: =DATEDIF(F17,TODAY(),"y") -> 20 | K17: ADICIONAL/MEJORAS | L17: 3 | M17: NO | N17: SOLICITADO | O17: No | Q17: RAÚL ANTONIO RODRIGUEZ DEL NOGAL | R17: 9094695 | S17: NUNCA HA TRABAJO PDVSA | T17: 8) Habite un inmueble bajo otra condición diferente a las anteriores
A18: 11 | B18: 16375125 | C18: EIRA ALEJANDRA LEÓN PEÑA | D18: RECURSOS HUMANOS | E18: ESCUELA | F18: =VLOOKUP(B18,Hoja2_2!$B$2:$G$110,6,0) -> 39904 | G18: =DATEDIF(F18,TODAY(),"y") -> 17 | K18: ADICIONAL/MEJORAS | L18: 4 | M18: NO | N18: SOLICITADO | O18: No | Q18: CESAR VELASQUEZ ZABALA | R18: 15428693 | S18: ES TRABAJADOR(A) ACTIVO(A) | T18: 8) Habite un inmueble bajo otra condición diferente a las anteriores
A19: 12 | B19: 17546584 | C19: ELIANA LIZKEIRA GONZÁLEZ PLAZA | D19: RECURSOS HUMANOS | E19: ESCUELA | F19: =VLOOKUP(B19,Hoja2_2!$B$2:$G$110,6,0) -> 41008 | G19: =DATEDIF(F19,TODAY(),"y") -> 14 | K19: ADICIONAL/MEJORAS | L19: 4 | M19: NO | N19: SOLICITADO | O19: No | Q19: RANDY PEREZ | R19: 14111920 | S19: NUNCA HA TRABAJO PDVSA | T19: 8) Habite un inmueble bajo otra condición diferente a las anteriores
A20: 13 | B20: 16374774 | C20: ELINOR DEL VALLE HURTADO MARCANO | D20: RECURSOS HUMANOS | E20: ESCUELA | F20: =VLOOKUP(B20,Hoja2_2!$B$2:$G$110,6,0) -> 41754 | G20: =DATEDIF(F20,TODAY(),"y") -> 12 | K20: INICIAL/ADQUISICIÓN | L20: 1 | M20: NO | N20: PAGANDOLO | O20: No | T20: 8) Habite un inmueble bajo otra condición diferente a las anteriores
A21: 14 | B21: 16699098 | C21: FERNANDA ELISAMA LÓPEZ CARRASQUERO | D21: RECURSOS HUMANOS | E21: ESCUELA | F21: =VLOOKUP(B21,Hoja2_2!$B$2:$G$110,6,0) -> 43473 | G21: =DATEDIF(F21,TODAY(),"y") -> 7 | K21: INICIAL/ADQUISICIÓN | L21: 2 | M21: NO | N21: PAGANDOLO | O21: No | Q21: DANIEL ENRIQUE CEDEÑO ZAPATA | R21: 12792653 | S21: ES TRABAJADOR(A) ACTIVO(A) | T21: 8) Habite un inmueble bajo otra condición diferente a las anteriores
A22: 15 | B22: 16397151 | C22: FERNANDO DANIEL SALAZAR GONZÁLEZ | D22: RECURSOS HUMANOS | E22: ESCUELA | F22: =VLOOKUP(B22,Hoja2_2!$B$2:$G$110,6,0) -> 41127 | G22: =DATEDIF(F22,TODAY(),"y") -> 13 | K22: ADICIONAL/MEJORAS | L22: 2 | M22: NO | N22: SOLICITADO | O22: No | Q22: CRISTINA DEL CARMEN PIAMO CALZADILLA | R22: 15336800 | S22: TRABAJÓ, ESTÁ RETIRADO | T22: 8) Habite un inmueble bajo otra condición diferente a las anteriores
A23: 16 | B23: 18172869 | C23: ISABEL MARÍA ALBORNOZ MARCANO | D23: RECURSOS HUMANOS | E23: ESCUELA | F23: =VLOOKUP(B23,Hoja2_2!$B$2:$G$110,6,0) -> 43473 | G23: =DATEDIF(F23,TODAY(),"y") -> 7 | K23: INICIAL/MEJORAS | L23: 3 | M23: NO | N23: SOLICITADO | O23: No | Q23: LUIS ALEJANDRO GUEVARA CABELLO | R23: 11449043 | S23: TRABAJÓ, ESTÁ RETIRADO | T23: 8) Habite un inmueble bajo otra condición diferente a las anteriores
A24: 17 | B24: 19038253 | C24: ISLENY ADRIANA FUENMAYOR LIPORACHI | D24: RECURSOS HUMANOS | E24: ESCUELA | F24: =VLOOKUP(B24,Hoja2_2!$B$2:$G$110,6,0) -> 41754 | G24: =DATEDIF(F24,TODAY(),"y") -> 12 | K24: INICIAL/ADQUISICIÓN | L24: 1 | M24: NO | N24: PAGANDOLO | O24: No | T24: 8) Habite un inmueble bajo otra condición diferente a las anteriores
A25: 18 | B25: 17722878 | C25: JAMNYMAR JOSÉ JIMÉNEZ DE MÁRQUEZ | D25: RECURSOS HUMANOS | E25: ESCUELA | F25: =VLOOKUP(B25,Hoja2_2!$B$2:$G$110,6,0) -> 40470 | G25: =DATEDIF(F25,TODAY(),"y") -> 15 | K25: ADICIONAL/MEJORAS | L25: 4 | M25: NO | N25: SOLICITADO | O25: No | Q25: CARLOS GABRIEL MÁRQUEZ SALAZAR | R25: 17713009 | S25: NUNCA HA TRABAJO PDVSA | T25: 8) Habite un inmueble bajo otra condición diferente a las anteriores
A26: 19 | B26: 16722294 | C26: JESLHOR KATHERINE BRITO HERNÁNDEZ | D26: RECURSOS HUMANOS | E26: ESCUELA | F26: =VLOOKUP(B26,Hoja2_2!$B$2:$G$110,6,0) -> 41624 | G26: =DATEDIF(F26,TODAY(),"y") -> 12 | K26: INICIAL/ADQUISICIÓN | L26: 1 | M26: NO | N26: PAGANDOLO | O26: No | T26: 8) Habite un inmueble bajo otra condición diferente a las anteriores
A27: 20 | B27: 14703619 | C27: JOSÉ ÁNGEL LUCAS CARRASQUEL | D27: RECURSOS HUMANOS | E27: ESCUELA | F27: =VLOOKUP(B27,Hoja2_2!$B$2:$G$110,6,0) -> 41008 | G27: =DATEDIF(F27,TODAY(),"y") -> 14 | K27: INICIAL/MEJORAS | L27: 5 | M27: NO | N27: SOLICITADO | O27: No | Q27: MARÍA GABRIELA SMITH DE LUCAS | R27: 18652761 | S27: ES TRABAJADOR(A) ACTIVO(A) | T27: 8) Habite un inmueble bajo otra condición diferente a las anteriores
A28: 21 | B28: 14859067 | C28: JUAN CARLOS CANELÓN | D28: RECURSOS HUMANOS | E28: ESCUELA | F28: =VLOOKUP(B28,Hoja2_2!$B$2:$G$110,6,0) -> 43473 | G28: =DATEDIF(F28,TODAY(),"y") -> 7 | K28: INICIAL/MEJORAS | L28: 2 | M28: NO | N28: SOLICITADO | O28: No | Q28: MARIELLYS GONZALES | R28: 16710266 | S28: NUNCA HA TRABAJO PDVSA | T28: 8) Habite un inmueble bajo otra condición diferente a las anteriores
A29: 22 | B29: 20001991 | C29: JUAN CRICELIO GONZÁLEZ BARCELO | D29: RECURSOS HUMANOS | E29: ESCUELA | F29: =VLOOKUP(B29,Hoja2_2!$B$2:$G$110,6,0) -> 44596 | G29: =DATEDIF(F29,TODAY(),"y") -> 4 | K29: INICIAL/ADQUISICIÓN | L29: 2 | M29: NO | N29: SOLICITADO | O29: No | Q29: YELIS DEL CARMEN HERNANDEZ RODRIGUEZ | R29: 20002235 | S29: NUNCA HA TRABAJO PDVSA | T29: 2) Habite en condición de arrimado, solo o con su grupo familiar.
A30: 23 | B30: 19875121 | C30: JULIA ISABEL RUIZ VILLARROEL | D30: RECURSOS HUMANOS | E30: ESCUELA | F30: =VLOOKUP(B30,Hoja2_2!$B$2:$G$110,6,0) -> 41754 | G30: =DATEDIF(F30,TODAY(),"y") -> 12 | K30: ADICIONAL/MEJORAS | L30: 2 | M30: NO | N30: SOLICITADO | O30: No | Q30: EDUARDO JOSÉ VELASQUEZ RODRÍGUEZ | R30: 17782202 | S30: ES TRABAJADOR(A) ACTIVO(A) | T30: 8) Habite un inmueble bajo otra condición diferente a las anteriores
A31: 24 | B31: 13092755 | C31: KARINA DEL VALLE BARRETO SERRANO | D31: RECURSOS HUMANOS | E31: ESCUELA | F31: =VLOOKUP(B31,Hoja2_2!$B$2:$G$110,6,0) -> 38302 | G31: =DATEDIF(F31,TODAY(),"y") -> 21 | K31: ADICIONAL/ADQUISICIÓN | L31: 2 | M31: NO | N31: SOLICITADO | O31: No | T31: 2) Habite en condición de arrimado, solo o con su grupo familiar.
A32: 25 | B32: 13656273 | C32: LAURYS DEL VALLE MILLÁN DE RIVAS | D32: RECURSOS HUMANOS | E32: ESCUELA | F32: =VLOOKUP(B32,Hoja2_2!$B$2:$G$110,6,0) -> 39461 | G32: =DATEDIF(F32,TODAY(),"y") -> 18 | K32: INICIAL/ADQUISICIÓN | L32: 4 | M32: NO | N32: PAGANDOLO | O32: No | Q32: JESÚS AQUILES RIVAS HERNÁNDEZ | R32: 9899154 | S32: ES TRABAJADOR(A) ACTIVO(A) | T32: 8) Habite un inmueble bajo otra condición diferente a las anteriores
A33: 26 | B33: 17483709 | C33: LORIANIS ZULLYN CELIZ CASTILLO | D33: RECURSOS HUMANOS | E33: ESCUELA | F33: =VLOOKUP(B33,Hoja2_2!$B$2:$G$110,6,0) -> 41222 | G33: =DATEDIF(F33,TODAY(),"y") -> 13 | K33: ADICIONAL/ADQUISICIÓN | L33: 3 | M33: NO | N33: SOLICITADO | O33: No | Q33: JOSÉ VICENTE MILLAN MONTAÑO | R33: 17780095 | S33: ES TRABAJADOR(A) ACTIVO(A) | T33: 6) Habite en vivienda prestada, bajo su cuidado.
A34: 27 | B34: 19079457 | C34: LUIS JOSE RIVAS ROMERO | D34: RECURSOS HUMANOS | E34: ESCUELA | F34: =VLOOKUP(B34,Hoja2_2!$B$2:$G$110,6,0) -> 43473 | G34: =DATEDIF(F34,TODAY(),"y") -> 7 | K34: INICIAL/ADQUISICIÓN | L34: 3 | M34: NO | N34: SOLICITADO | O34: No | T34: 5) Habite en vivienda catalogada de alto riesgo, así declarado por la autoridad competente (Protección Civil o Bomberos)
A35: 28 | B35: 17723779 | C35: LUISA JOSÉ JIMÉNEZ NUÑEZ | D35: RECURSOS HUMANOS | E35: ESCUELA | F35: =VLOOKUP(B35,Hoja2_2!$B$2:$G$110,6,0) -> 43473 | G35: =DATEDIF(F35,TODAY(),"y") -> 7 | K35: INICIAL/ADQUISICIÓN | L35: 3 | M35: NO | N35: SOLICITADO | O35: No | Q35: MANRIQUE MANUEL ALEJANDRO | R35: 16691883 | S35: NUNCA HA TRABAJO PDVSA | T35: 6) Habite en vivienda prestada, bajo su cuidado.
A36: 29 | B36: 17463095 | C36: MARÍA JOSÉ MARTÍNEZ OLIVEROS | D36: RECURSOS HUMANOS | E36: ESCUELA | F36: =VLOOKUP(B36,Hoja2_2!$B$2:$G$110,6,0) -> 43473 | G36: =DATEDIF(F36,TODAY(),"y") -> 7 | K36: INICIAL/ADQUISICIÓN | L36: 1 | M36: NO | N36: SOLICITADO | O36: No | Q36: ALEJANDRO JOSÉ RODRÍGUEZ VILLARROEL | R36: 16926442 | S36: ES TRABAJADOR(A) ACTIVO(A) | T36: 6) Habite en vivienda prestada, bajo su cuidado.
A37: 30 | B37: 17241569 | C37: MARTÍN EDUARDO MARCANO | D37: RECURSOS HUMANOS | E37: ESCUELA | F37: =VLOOKUP(B37,Hoja2_2!$B$2:$G$110,6,0) -> 41754 | G37: =DATEDIF(F37,TODAY(),"y") -> 12 | K37: ADICIONAL/MEJORAS | L37: 3 | M37: NO | N37: SOLICITADO | O37: No | Q37: TERESA CORTEZ | R37: 16710908 | S37: NUNCA HA TRABAJO PDVSA | T37: 8) Habite un inmueble bajo otra condición diferente a las anteriores
A38: 31 | B38: 14531830 | C38: MINERVA JOSEFINA MARTIN GUZMAN | D38: RECURSOS HUMANOS | E38: ESCUELA | F38: =VLOOKUP(B38,Hoja2_2!$B$2:$G$110,6,0) -> 43108 | G38: =DATEDIF(F38,TODAY(),"y") -> 8 | K38: INICIAL/ADQUISICIÓN | L38: 2 | M38: NO | N38: SOLICITADO | O38: No | Q38: PEDRO RAMON TINEO PALMA | R38: 13544171 | S38: ES TRABAJADOR(A) ACTIVO(A) | T38: 8) Habite un inmueble bajo otra condición diferente a las anteriores
A39: 32 | B39: 12067865 | C39: NEIDA MARGARITA GARCIA DE ROJAS | D39: RECURSOS HUMANOS | E39: ESCUELA | F39: =VLOOKUP(B39,Hoja2_2!$B$2:$G$110,6,0) -> 41628 | G39: =DATEDIF(F39,TODAY(),"y") -> 12 | K39: INICIAL/ADQUISICIÓN | L39: 2 | M39: NO | N39: PAGANDOLO | O39: No | T39: 8) Habite un inmueble bajo otra condición diferente a las anteriores
A40: 33 | B40: 11830987 | C40: OLGA ALICIA PARRA SALAZAR | D40: RECURSOS HUMANOS | E40: ESCUELA | F40: =VLOOKUP(B40,Hoja2_2!$B$2:$G$110,6,0) -> 37151 | G40: =DATEDIF(F40,TODAY(),"y") -> 24 | K40: ADICIONAL/MEJORAS | L40: 3 | M40: NO | N40: PAGADO | O40: No | Q40: JORGE LUIS APONTE SOSA | R40: 13452820 | S40: NUNCA HA TRABAJO PDVSA | T40: 8) Habite un inmueble bajo otra condición diferente a las anteriores
A41: 34 | B41: 16174810 | C41: OMAR RAFAEL RIVAS VILLARROEL | D41: RECURSOS HUMANOS | E41: ESCUELA | F41: =VLOOKUP(B41,Hoja2_2!$B$2:$G$110,6,0) -> 43837 | G41: =DATEDIF(F41,TODAY(),"y") -> 6 | K41: INICIAL/ADQUISICIÓN | L41: 2 | M41: NO | N41: PAGANDOLO | O41: No | T41: 8) Habite un inmueble bajo otra condición diferente a las anteriores
...
